2025-07-29 16:07:01 - app.core.permission_cache - ERROR - 设置权限缓存策略失败: 'CacheManager' object has no attribute 'add_strategy'
2025-07-29 16:07:28 - app.core.permission_cache - ERROR - 设置权限缓存策略失败: 'CacheManager' object has no attribute 'add_strategy'
2025-07-31 17:56:21 - app.core.cache_warmup - ERROR - 预热用户权限缓存失败: 'CRUDUser' object has no attribute 'get_active_users'
2025-07-31 17:56:21 - app.core.cache_warmup - ERROR - 缓存预热失败: 'CRUDUser' object has no attribute 'get_active_users'
2025-07-31 17:56:21 - app.core.cache_warmup - ERROR - 启动缓存预热失败: 'CRUDUser' object has no attribute 'get_active_users'
2025-07-31 18:01:21 - app.core.cache_warmup - ERROR - 预热关键权限数据失败: 'CRUDUser' object has no attribute 'get_all_users'
2025-07-31 18:01:21 - app.core.cache_warmup - ERROR - 定期缓存刷新失败: 'CRUDUser' object has no attribute 'get_all_users'
2025-07-31 18:06:21 - app.core.cache_warmup - ERROR - 预热关键权限数据失败: 'CRUDUser' object has no attribute 'get_all_users'
2025-07-31 18:06:21 - app.core.cache_warmup - ERROR - 定期缓存刷新失败: 'CRUDUser' object has no attribute 'get_all_users'
2025-07-31 18:11:21 - app.core.cache_warmup - ERROR - 预热关键权限数据失败: 'CRUDUser' object has no attribute 'get_all_users'
2025-07-31 18:11:21 - app.core.cache_warmup - ERROR - 定期缓存刷新失败: 'CRUDUser' object has no attribute 'get_all_users'
2025-07-31 18:16:21 - app.core.cache_warmup - ERROR - 预热关键权限数据失败: 'CRUDUser' object has no attribute 'get_all_users'
2025-07-31 18:16:21 - app.core.cache_warmup - ERROR - 定期缓存刷新失败: 'CRUDUser' object has no attribute 'get_all_users'
2025-07-31 18:21:21 - app.core.cache_warmup - ERROR - 预热关键权限数据失败: 'CRUDUser' object has no attribute 'get_all_users'
2025-07-31 18:21:21 - app.core.cache_warmup - ERROR - 定期缓存刷新失败: 'CRUDUser' object has no attribute 'get_all_users'
2025-07-31 18:26:21 - app.core.cache_warmup - ERROR - 预热关键权限数据失败: 'CRUDUser' object has no attribute 'get_all_users'
2025-07-31 18:26:21 - app.core.cache_warmup - ERROR - 定期缓存刷新失败: 'CRUDUser' object has no attribute 'get_all_users'
2025-07-31 18:31:21 - app.core.cache_warmup - ERROR - 预热关键权限数据失败: 'CRUDUser' object has no attribute 'get_all_users'
2025-07-31 18:31:21 - app.core.cache_warmup - ERROR - 定期缓存刷新失败: 'CRUDUser' object has no attribute 'get_all_users'
2025-07-31 18:36:21 - app.core.cache_warmup - ERROR - 预热关键权限数据失败: 'CRUDUser' object has no attribute 'get_all_users'
2025-07-31 18:36:21 - app.core.cache_warmup - ERROR - 定期缓存刷新失败: 'CRUDUser' object has no attribute 'get_all_users'
2025-07-31 18:41:21 - app.core.cache_warmup - ERROR - 预热关键权限数据失败: 'CRUDUser' object has no attribute 'get_all_users'
2025-07-31 18:41:21 - app.core.cache_warmup - ERROR - 定期缓存刷新失败: 'CRUDUser' object has no attribute 'get_all_users'
2025-07-31 18:46:21 - app.core.cache_warmup - ERROR - 预热关键权限数据失败: 'CRUDUser' object has no attribute 'get_all_users'
2025-07-31 18:46:21 - app.core.cache_warmup - ERROR - 定期缓存刷新失败: 'CRUDUser' object has no attribute 'get_all_users'
2025-07-31 18:51:21 - app.core.cache_warmup - ERROR - 预热关键权限数据失败: 'CRUDUser' object has no attribute 'get_all_users'
2025-07-31 18:51:21 - app.core.cache_warmup - ERROR - 定期缓存刷新失败: 'CRUDUser' object has no attribute 'get_all_users'
2025-07-31 18:56:21 - app.core.cache_warmup - ERROR - 预热关键权限数据失败: 'CRUDUser' object has no attribute 'get_all_users'
2025-07-31 18:56:21 - app.core.cache_warmup - ERROR - 定期缓存刷新失败: 'CRUDUser' object has no attribute 'get_all_users'
2025-07-31 19:01:21 - app.core.cache_warmup - ERROR - 预热关键权限数据失败: 'CRUDUser' object has no attribute 'get_all_users'
2025-07-31 19:01:21 - app.core.cache_warmup - ERROR - 定期缓存刷新失败: 'CRUDUser' object has no attribute 'get_all_users'
2025-07-31 19:06:21 - app.core.cache_warmup - ERROR - 预热关键权限数据失败: 'CRUDUser' object has no attribute 'get_all_users'
2025-07-31 19:06:21 - app.core.cache_warmup - ERROR - 定期缓存刷新失败: 'CRUDUser' object has no attribute 'get_all_users'
2025-07-31 19:11:21 - app.core.cache_warmup - ERROR - 预热关键权限数据失败: 'CRUDUser' object has no attribute 'get_all_users'
2025-07-31 19:11:21 - app.core.cache_warmup - ERROR - 定期缓存刷新失败: 'CRUDUser' object has no attribute 'get_all_users'
2025-07-31 19:16:21 - app.core.cache_warmup - ERROR - 预热关键权限数据失败: 'CRUDUser' object has no attribute 'get_all_users'
2025-07-31 19:16:21 - app.core.cache_warmup - ERROR - 定期缓存刷新失败: 'CRUDUser' object has no attribute 'get_all_users'
2025-07-31 19:21:21 - app.core.cache_warmup - ERROR - 预热关键权限数据失败: 'CRUDUser' object has no attribute 'get_all_users'
2025-07-31 19:21:21 - app.core.cache_warmup - ERROR - 定期缓存刷新失败: 'CRUDUser' object has no attribute 'get_all_users'
2025-07-31 19:26:21 - app.core.cache_warmup - ERROR - 预热关键权限数据失败: 'CRUDUser' object has no attribute 'get_all_users'
2025-07-31 19:26:21 - app.core.cache_warmup - ERROR - 定期缓存刷新失败: 'CRUDUser' object has no attribute 'get_all_users'
2025-07-31 19:31:21 - app.core.cache_warmup - ERROR - 预热关键权限数据失败: 'CRUDUser' object has no attribute 'get_all_users'
2025-07-31 19:31:21 - app.core.cache_warmup - ERROR - 定期缓存刷新失败: 'CRUDUser' object has no attribute 'get_all_users'
2025-07-31 19:36:21 - app.core.cache_warmup - ERROR - 预热关键权限数据失败: 'CRUDUser' object has no attribute 'get_all_users'
2025-07-31 19:36:21 - app.core.cache_warmup - ERROR - 定期缓存刷新失败: 'CRUDUser' object has no attribute 'get_all_users'
2025-07-31 19:41:21 - app.core.cache_warmup - ERROR - 预热关键权限数据失败: 'CRUDUser' object has no attribute 'get_all_users'
2025-07-31 19:41:21 - app.core.cache_warmup - ERROR - 定期缓存刷新失败: 'CRUDUser' object has no attribute 'get_all_users'
2025-07-31 19:46:21 - app.core.cache_warmup - ERROR - 预热关键权限数据失败: 'CRUDUser' object has no attribute 'get_all_users'
2025-07-31 19:46:21 - app.core.cache_warmup - ERROR - 定期缓存刷新失败: 'CRUDUser' object has no attribute 'get_all_users'
2025-07-31 19:51:21 - app.core.cache_warmup - ERROR - 预热关键权限数据失败: 'CRUDUser' object has no attribute 'get_all_users'
2025-07-31 19:51:21 - app.core.cache_warmup - ERROR - 定期缓存刷新失败: 'CRUDUser' object has no attribute 'get_all_users'
2025-07-31 19:56:21 - app.core.cache_warmup - ERROR - 预热关键权限数据失败: 'CRUDUser' object has no attribute 'get_all_users'
2025-07-31 19:56:21 - app.core.cache_warmup - ERROR - 定期缓存刷新失败: 'CRUDUser' object has no attribute 'get_all_users'
2025-07-31 20:01:21 - app.core.cache_warmup - ERROR - 预热关键权限数据失败: 'CRUDUser' object has no attribute 'get_all_users'
2025-07-31 20:01:21 - app.core.cache_warmup - ERROR - 定期缓存刷新失败: 'CRUDUser' object has no attribute 'get_all_users'
2025-07-31 20:06:21 - app.core.cache_warmup - ERROR - 预热关键权限数据失败: 'CRUDUser' object has no attribute 'get_all_users'
2025-07-31 20:06:21 - app.core.cache_warmup - ERROR - 定期缓存刷新失败: 'CRUDUser' object has no attribute 'get_all_users'
2025-07-31 20:11:21 - app.core.cache_warmup - ERROR - 预热关键权限数据失败: 'CRUDUser' object has no attribute 'get_all_users'
2025-07-31 20:11:21 - app.core.cache_warmup - ERROR - 定期缓存刷新失败: 'CRUDUser' object has no attribute 'get_all_users'
2025-07-31 20:16:21 - app.core.cache_warmup - ERROR - 预热关键权限数据失败: 'CRUDUser' object has no attribute 'get_all_users'
2025-07-31 20:16:21 - app.core.cache_warmup - ERROR - 定期缓存刷新失败: 'CRUDUser' object has no attribute 'get_all_users'
2025-07-31 20:17:47 - app.core.exceptions - ERROR - HTTP Exception: 401 - Could not validate credentials: Signature verification failed.
2025-07-31 20:18:26 - app.core.exceptions - ERROR - Validation Exception: [{'type': 'missing', 'loc': ('body', 'username'), 'msg': 'Field required', 'input': None}, {'type': 'missing', 'loc': ('body', 'password'), 'msg': 'Field required', 'input': None}]
2025-07-31 20:21:21 - app.core.cache_warmup - ERROR - 预热关键权限数据失败: 'CRUDUser' object has no attribute 'get_all_users'
2025-07-31 20:21:21 - app.core.cache_warmup - ERROR - 定期缓存刷新失败: 'CRUDUser' object has no attribute 'get_all_users'
2025-07-31 20:26:21 - app.core.cache_warmup - ERROR - 预热关键权限数据失败: 'CRUDUser' object has no attribute 'get_all_users'
2025-07-31 20:26:21 - app.core.cache_warmup - ERROR - 定期缓存刷新失败: 'CRUDUser' object has no attribute 'get_all_users'
2025-07-31 20:26:40 - app.core.cache_warmup - ERROR - 预热用户权限缓存失败: 'CRUDUser' object has no attribute 'get_active_users'
2025-07-31 20:26:40 - app.core.cache_warmup - ERROR - 缓存预热失败: 'CRUDUser' object has no attribute 'get_active_users'
2025-07-31 20:26:40 - app.core.cache_warmup - ERROR - 启动缓存预热失败: 'CRUDUser' object has no attribute 'get_active_users'
2025-07-31 20:31:40 - app.core.cache_warmup - ERROR - 预热关键权限数据失败: 'CRUDUser' object has no attribute 'get_all_users'
2025-07-31 20:31:40 - app.core.cache_warmup - ERROR - 定期缓存刷新失败: 'CRUDUser' object has no attribute 'get_all_users'
2025-07-31 20:35:38 - app.core.exceptions - ERROR - HTTP Exception: 401 - Could not validate credentials: Signature verification failed.
2025-07-31 20:36:40 - app.core.cache_warmup - ERROR - 预热关键权限数据失败: 'CRUDUser' object has no attribute 'get_all_users'
2025-07-31 20:36:40 - app.core.cache_warmup - ERROR - 定期缓存刷新失败: 'CRUDUser' object has no attribute 'get_all_users'
2025-07-31 20:41:40 - app.core.cache_warmup - ERROR - 预热关键权限数据失败: 'CRUDUser' object has no attribute 'get_all_users'
2025-07-31 20:41:40 - app.core.cache_warmup - ERROR - 定期缓存刷新失败: 'CRUDUser' object has no attribute 'get_all_users'
2025-07-31 20:46:40 - app.core.cache_warmup - ERROR - 预热关键权限数据失败: 'CRUDUser' object has no attribute 'get_all_users'
2025-07-31 20:46:40 - app.core.cache_warmup - ERROR - 定期缓存刷新失败: 'CRUDUser' object has no attribute 'get_all_users'
2025-07-31 20:51:40 - app.core.cache_warmup - ERROR - 预热关键权限数据失败: 'CRUDUser' object has no attribute 'get_all_users'
2025-07-31 20:51:40 - app.core.cache_warmup - ERROR - 定期缓存刷新失败: 'CRUDUser' object has no attribute 'get_all_users'
2025-08-05 03:09:51 - app.services.cache_init - ERROR - Failed to initialize cache service: Error 11001 connecting to redis:6379. getaddrinfo failed.
2025-08-05 03:09:51 - app.services.cache_init - ERROR - Cache system initialization failed: Error 11001 connecting to redis:6379. getaddrinfo failed.
2025-08-05 03:10:10 - app.core.exceptions - ERROR - HTTP Exception: 401 - Could not validate credentials: Not enough segments
2025-08-05 03:10:10 - app.core.exceptions - ERROR - HTTP Exception: 401 - Could not validate credentials: Not enough segments
2025-08-05 08:30:24 - app.services.cache_init - ERROR - Failed to initialize cache service: Error 11001 connecting to redis:6379. getaddrinfo failed.
2025-08-05 08:30:24 - app.services.cache_init - ERROR - Cache system initialization failed: Error 11001 connecting to redis:6379. getaddrinfo failed.
2025-08-05 08:31:36 - app.services.cache_init - ERROR - Failed to initialize cache service: Error 11001 connecting to redis:6379. getaddrinfo failed.
2025-08-05 08:31:36 - app.services.cache_init - ERROR - Cache system initialization failed: Error 11001 connecting to redis:6379. getaddrinfo failed.
2025-08-05 08:36:36 - app.core.cache_warmup - ERROR - 预热关键权限数据失败: (psycopg2.OperationalError) connection to server at "127.0.0.1", port 5432 failed: FATAL:  password authentication failed for user "sys_rev_user"

(Background on this error at: https://sqlalche.me/e/20/e3q8)
2025-08-05 08:36:36 - app.core.cache_warmup - ERROR - 定期缓存刷新失败: (psycopg2.OperationalError) connection to server at "127.0.0.1", port 5432 failed: FATAL:  password authentication failed for user "sys_rev_user"

(Background on this error at: https://sqlalche.me/e/20/e3q8)
2025-08-05 08:41:36 - app.core.cache_warmup - ERROR - 预热关键权限数据失败: (psycopg2.OperationalError) connection to server at "127.0.0.1", port 5432 failed: FATAL:  password authentication failed for user "sys_rev_user"

(Background on this error at: https://sqlalche.me/e/20/e3q8)
2025-08-05 08:41:36 - app.core.cache_warmup - ERROR - 定期缓存刷新失败: (psycopg2.OperationalError) connection to server at "127.0.0.1", port 5432 failed: FATAL:  password authentication failed for user "sys_rev_user"

(Background on this error at: https://sqlalche.me/e/20/e3q8)
2025-08-05 08:46:36 - app.core.cache_warmup - ERROR - 预热关键权限数据失败: (psycopg2.OperationalError) connection to server at "127.0.0.1", port 5432 failed: FATAL:  password authentication failed for user "sys_rev_user"

(Background on this error at: https://sqlalche.me/e/20/e3q8)
2025-08-05 08:46:36 - app.core.cache_warmup - ERROR - 定期缓存刷新失败: (psycopg2.OperationalError) connection to server at "127.0.0.1", port 5432 failed: FATAL:  password authentication failed for user "sys_rev_user"

(Background on this error at: https://sqlalche.me/e/20/e3q8)
2025-08-05 08:51:36 - app.core.cache_warmup - ERROR - 预热关键权限数据失败: (psycopg2.OperationalError) connection to server at "127.0.0.1", port 5432 failed: FATAL:  password authentication failed for user "sys_rev_user"

(Background on this error at: https://sqlalche.me/e/20/e3q8)
2025-08-05 08:51:36 - app.core.cache_warmup - ERROR - 定期缓存刷新失败: (psycopg2.OperationalError) connection to server at "127.0.0.1", port 5432 failed: FATAL:  password authentication failed for user "sys_rev_user"

(Background on this error at: https://sqlalche.me/e/20/e3q8)
2025-08-05 08:56:36 - app.core.cache_warmup - ERROR - 预热关键权限数据失败: (psycopg2.OperationalError) connection to server at "127.0.0.1", port 5432 failed: FATAL:  password authentication failed for user "sys_rev_user"

(Background on this error at: https://sqlalche.me/e/20/e3q8)
2025-08-05 08:56:36 - app.core.cache_warmup - ERROR - 定期缓存刷新失败: (psycopg2.OperationalError) connection to server at "127.0.0.1", port 5432 failed: FATAL:  password authentication failed for user "sys_rev_user"

(Background on this error at: https://sqlalche.me/e/20/e3q8)
2025-08-05 09:01:36 - app.core.cache_warmup - ERROR - 预热关键权限数据失败: (psycopg2.OperationalError) connection to server at "127.0.0.1", port 5432 failed: FATAL:  password authentication failed for user "sys_rev_user"

(Background on this error at: https://sqlalche.me/e/20/e3q8)
2025-08-05 09:01:36 - app.core.cache_warmup - ERROR - 定期缓存刷新失败: (psycopg2.OperationalError) connection to server at "127.0.0.1", port 5432 failed: FATAL:  password authentication failed for user "sys_rev_user"

(Background on this error at: https://sqlalche.me/e/20/e3q8)
2025-08-05 09:06:36 - app.core.cache_warmup - ERROR - 预热关键权限数据失败: (psycopg2.OperationalError) connection to server at "127.0.0.1", port 5432 failed: FATAL:  password authentication failed for user "sys_rev_user"

(Background on this error at: https://sqlalche.me/e/20/e3q8)
2025-08-05 09:06:36 - app.core.cache_warmup - ERROR - 定期缓存刷新失败: (psycopg2.OperationalError) connection to server at "127.0.0.1", port 5432 failed: FATAL:  password authentication failed for user "sys_rev_user"

(Background on this error at: https://sqlalche.me/e/20/e3q8)
2025-08-05 09:11:36 - app.core.cache_warmup - ERROR - 预热关键权限数据失败: (psycopg2.OperationalError) connection to server at "127.0.0.1", port 5432 failed: FATAL:  password authentication failed for user "sys_rev_user"

(Background on this error at: https://sqlalche.me/e/20/e3q8)
2025-08-05 09:11:36 - app.core.cache_warmup - ERROR - 定期缓存刷新失败: (psycopg2.OperationalError) connection to server at "127.0.0.1", port 5432 failed: FATAL:  password authentication failed for user "sys_rev_user"

(Background on this error at: https://sqlalche.me/e/20/e3q8)
2025-08-05 09:16:36 - app.core.cache_warmup - ERROR - 预热关键权限数据失败: (psycopg2.OperationalError) connection to server at "127.0.0.1", port 5432 failed: FATAL:  password authentication failed for user "sys_rev_user"

(Background on this error at: https://sqlalche.me/e/20/e3q8)
2025-08-05 09:16:36 - app.core.cache_warmup - ERROR - 定期缓存刷新失败: (psycopg2.OperationalError) connection to server at "127.0.0.1", port 5432 failed: FATAL:  password authentication failed for user "sys_rev_user"

(Background on this error at: https://sqlalche.me/e/20/e3q8)
2025-08-05 09:21:36 - app.core.cache_warmup - ERROR - 预热关键权限数据失败: (psycopg2.OperationalError) connection to server at "127.0.0.1", port 5432 failed: FATAL:  password authentication failed for user "sys_rev_user"

(Background on this error at: https://sqlalche.me/e/20/e3q8)
2025-08-05 09:21:36 - app.core.cache_warmup - ERROR - 定期缓存刷新失败: (psycopg2.OperationalError) connection to server at "127.0.0.1", port 5432 failed: FATAL:  password authentication failed for user "sys_rev_user"

(Background on this error at: https://sqlalche.me/e/20/e3q8)
2025-08-05 09:26:36 - app.core.cache_warmup - ERROR - 预热关键权限数据失败: (psycopg2.OperationalError) connection to server at "127.0.0.1", port 5432 failed: FATAL:  password authentication failed for user "sys_rev_user"

(Background on this error at: https://sqlalche.me/e/20/e3q8)
2025-08-05 09:26:36 - app.core.cache_warmup - ERROR - 定期缓存刷新失败: (psycopg2.OperationalError) connection to server at "127.0.0.1", port 5432 failed: FATAL:  password authentication failed for user "sys_rev_user"

(Background on this error at: https://sqlalche.me/e/20/e3q8)
2025-08-05 09:31:36 - app.core.cache_warmup - ERROR - 预热关键权限数据失败: (psycopg2.OperationalError) connection to server at "127.0.0.1", port 5432 failed: FATAL:  password authentication failed for user "sys_rev_user"

(Background on this error at: https://sqlalche.me/e/20/e3q8)
2025-08-05 09:31:36 - app.core.cache_warmup - ERROR - 定期缓存刷新失败: (psycopg2.OperationalError) connection to server at "127.0.0.1", port 5432 failed: FATAL:  password authentication failed for user "sys_rev_user"

(Background on this error at: https://sqlalche.me/e/20/e3q8)
2025-08-05 09:36:36 - app.core.cache_warmup - ERROR - 预热关键权限数据失败: (psycopg2.OperationalError) connection to server at "127.0.0.1", port 5432 failed: FATAL:  password authentication failed for user "sys_rev_user"

(Background on this error at: https://sqlalche.me/e/20/e3q8)
2025-08-05 09:36:36 - app.core.cache_warmup - ERROR - 定期缓存刷新失败: (psycopg2.OperationalError) connection to server at "127.0.0.1", port 5432 failed: FATAL:  password authentication failed for user "sys_rev_user"

(Background on this error at: https://sqlalche.me/e/20/e3q8)
2025-08-05 09:41:36 - app.core.cache_warmup - ERROR - 预热关键权限数据失败: (psycopg2.OperationalError) connection to server at "127.0.0.1", port 5432 failed: FATAL:  password authentication failed for user "sys_rev_user"

(Background on this error at: https://sqlalche.me/e/20/e3q8)
2025-08-05 09:41:36 - app.core.cache_warmup - ERROR - 定期缓存刷新失败: (psycopg2.OperationalError) connection to server at "127.0.0.1", port 5432 failed: FATAL:  password authentication failed for user "sys_rev_user"

(Background on this error at: https://sqlalche.me/e/20/e3q8)
2025-08-05 09:46:36 - app.core.cache_warmup - ERROR - 预热关键权限数据失败: (psycopg2.OperationalError) connection to server at "127.0.0.1", port 5432 failed: FATAL:  password authentication failed for user "sys_rev_user"

(Background on this error at: https://sqlalche.me/e/20/e3q8)
2025-08-05 09:46:36 - app.core.cache_warmup - ERROR - 定期缓存刷新失败: (psycopg2.OperationalError) connection to server at "127.0.0.1", port 5432 failed: FATAL:  password authentication failed for user "sys_rev_user"

(Background on this error at: https://sqlalche.me/e/20/e3q8)
2025-08-05 09:50:42 - app.core.exceptions - ERROR - HTTP Exception: 401 - Could not validate credentials: Not enough segments
2025-08-05 09:50:42 - app.core.exceptions - ERROR - HTTP Exception: 401 - Could not validate credentials: Not enough segments
2025-08-05 09:51:09 - app.core.exceptions - ERROR - HTTP Exception: 401 - Could not validate credentials: Not enough segments
2025-08-05 09:51:09 - app.core.exceptions - ERROR - HTTP Exception: 401 - Could not validate credentials: Not enough segments
2025-08-05 09:51:13 - app.core.exceptions - ERROR - HTTP Exception: 401 - Could not validate credentials: Not enough segments
2025-08-05 09:51:13 - app.core.exceptions - ERROR - HTTP Exception: 401 - Could not validate credentials: Not enough segments
2025-08-05 09:51:37 - app.core.cache_warmup - ERROR - 预热关键权限数据失败: (psycopg2.OperationalError) connection to server at "127.0.0.1", port 5432 failed: FATAL:  password authentication failed for user "sys_rev_user"

(Background on this error at: https://sqlalche.me/e/20/e3q8)
2025-08-05 09:51:37 - app.core.cache_warmup - ERROR - 定期缓存刷新失败: (psycopg2.OperationalError) connection to server at "127.0.0.1", port 5432 failed: FATAL:  password authentication failed for user "sys_rev_user"

(Background on this error at: https://sqlalche.me/e/20/e3q8)
2025-08-05 09:56:01 - app.services.cache_init - ERROR - Failed to initialize cache service: Error 11001 connecting to redis:6379. getaddrinfo failed.
2025-08-05 09:56:01 - app.services.cache_init - ERROR - Cache system initialization failed: Error 11001 connecting to redis:6379. getaddrinfo failed.
2025-08-05 09:56:08 - app.services.cache_init - ERROR - Failed to initialize cache service: Error 11001 connecting to redis:6379. getaddrinfo failed.
2025-08-05 09:56:08 - app.services.cache_init - ERROR - Cache system initialization failed: Error 11001 connecting to redis:6379. getaddrinfo failed.
2025-08-05 09:56:45 - app.services.cache_init - ERROR - Failed to initialize cache service: Error 11001 connecting to redis:6379. getaddrinfo failed.
2025-08-05 09:56:45 - app.services.cache_init - ERROR - Cache system initialization failed: Error 11001 connecting to redis:6379. getaddrinfo failed.
2025-08-05 09:56:52 - app.services.cache_init - ERROR - Failed to initialize cache service: Error 11001 connecting to redis:6379. getaddrinfo failed.
2025-08-05 09:56:52 - app.services.cache_init - ERROR - Cache system initialization failed: Error 11001 connecting to redis:6379. getaddrinfo failed.
2025-08-05 09:57:05 - app.services.cache_init - ERROR - Failed to initialize cache service: Error 11001 connecting to redis:6379. getaddrinfo failed.
2025-08-05 09:57:05 - app.services.cache_init - ERROR - Cache system initialization failed: Error 11001 connecting to redis:6379. getaddrinfo failed.
2025-08-05 09:57:51 - app.services.cache_init - ERROR - Failed to initialize cache service: Error 11001 connecting to redis:6379. getaddrinfo failed.
2025-08-05 09:57:51 - app.services.cache_init - ERROR - Cache system initialization failed: Error 11001 connecting to redis:6379. getaddrinfo failed.
2025-08-05 09:58:07 - app.services.cache_init - ERROR - Failed to initialize cache service: Error 11001 connecting to redis:6379. getaddrinfo failed.
2025-08-05 09:58:07 - app.services.cache_init - ERROR - Cache system initialization failed: Error 11001 connecting to redis:6379. getaddrinfo failed.
2025-08-05 09:58:27 - app.services.cache_init - ERROR - Failed to initialize cache service: Error 11001 connecting to redis:6379. getaddrinfo failed.
2025-08-05 09:58:27 - app.services.cache_init - ERROR - Cache system initialization failed: Error 11001 connecting to redis:6379. getaddrinfo failed.
2025-08-05 09:58:41 - app.services.cache_init - ERROR - Failed to initialize cache service: Error 11001 connecting to redis:6379. getaddrinfo failed.
2025-08-05 09:58:41 - app.services.cache_init - ERROR - Cache system initialization failed: Error 11001 connecting to redis:6379. getaddrinfo failed.
2025-08-05 09:58:56 - app.services.cache_init - ERROR - Failed to initialize cache service: Error 11001 connecting to redis:6379. getaddrinfo failed.
2025-08-05 09:58:56 - app.services.cache_init - ERROR - Cache system initialization failed: Error 11001 connecting to redis:6379. getaddrinfo failed.
2025-08-05 09:59:15 - app.services.cache_init - ERROR - Failed to initialize cache service: Error 11001 connecting to redis:6379. getaddrinfo failed.
2025-08-05 09:59:15 - app.services.cache_init - ERROR - Cache system initialization failed: Error 11001 connecting to redis:6379. getaddrinfo failed.
2025-08-05 09:59:30 - app.services.cache_init - ERROR - Failed to initialize cache service: Error 11001 connecting to redis:6379. getaddrinfo failed.
2025-08-05 09:59:30 - app.services.cache_init - ERROR - Cache system initialization failed: Error 11001 connecting to redis:6379. getaddrinfo failed.
2025-08-05 09:59:37 - app.services.cache_init - ERROR - Failed to initialize cache service: Error 11001 connecting to redis:6379. getaddrinfo failed.
2025-08-05 09:59:37 - app.services.cache_init - ERROR - Cache system initialization failed: Error 11001 connecting to redis:6379. getaddrinfo failed.
2025-08-05 09:59:54 - app.services.cache_init - ERROR - Failed to initialize cache service: Error 11001 connecting to redis:6379. getaddrinfo failed.
2025-08-05 09:59:54 - app.services.cache_init - ERROR - Cache system initialization failed: Error 11001 connecting to redis:6379. getaddrinfo failed.
2025-08-05 10:00:01 - app.services.cache_init - ERROR - Failed to initialize cache service: Error 11001 connecting to redis:6379. getaddrinfo failed.
2025-08-05 10:00:01 - app.services.cache_init - ERROR - Cache system initialization failed: Error 11001 connecting to redis:6379. getaddrinfo failed.
2025-08-05 10:00:48 - app.services.cache_init - ERROR - Failed to initialize cache service: Error 11001 connecting to redis:6379. getaddrinfo failed.
2025-08-05 10:00:48 - app.services.cache_init - ERROR - Cache system initialization failed: Error 11001 connecting to redis:6379. getaddrinfo failed.
2025-08-05 10:01:06 - app.services.cache_init - ERROR - Failed to initialize cache service: Error 11001 connecting to redis:6379. getaddrinfo failed.
2025-08-05 10:01:06 - app.services.cache_init - ERROR - Cache system initialization failed: Error 11001 connecting to redis:6379. getaddrinfo failed.
2025-08-05 10:01:13 - app.services.cache_init - ERROR - Failed to initialize cache service: Error 11001 connecting to redis:6379. getaddrinfo failed.
2025-08-05 10:01:13 - app.services.cache_init - ERROR - Cache system initialization failed: Error 11001 connecting to redis:6379. getaddrinfo failed.
2025-08-05 10:01:25 - app.services.cache_init - ERROR - Failed to initialize cache service: Error 11001 connecting to redis:6379. getaddrinfo failed.
2025-08-05 10:01:25 - app.services.cache_init - ERROR - Cache system initialization failed: Error 11001 connecting to redis:6379. getaddrinfo failed.
2025-08-05 10:01:32 - app.services.cache_init - ERROR - Failed to initialize cache service: Error 11001 connecting to redis:6379. getaddrinfo failed.
2025-08-05 10:01:32 - app.services.cache_init - ERROR - Cache system initialization failed: Error 11001 connecting to redis:6379. getaddrinfo failed.
2025-08-05 10:01:43 - app.services.cache_init - ERROR - Failed to initialize cache service: Error 11001 connecting to redis:6379. getaddrinfo failed.
2025-08-05 10:01:43 - app.services.cache_init - ERROR - Cache system initialization failed: Error 11001 connecting to redis:6379. getaddrinfo failed.
2025-08-05 10:01:50 - app.services.cache_init - ERROR - Failed to initialize cache service: Error 11001 connecting to redis:6379. getaddrinfo failed.
2025-08-05 10:01:50 - app.services.cache_init - ERROR - Cache system initialization failed: Error 11001 connecting to redis:6379. getaddrinfo failed.
2025-08-05 10:01:57 - app.services.cache_init - ERROR - Failed to initialize cache service: Error 11001 connecting to redis:6379. getaddrinfo failed.
2025-08-05 10:01:57 - app.services.cache_init - ERROR - Cache system initialization failed: Error 11001 connecting to redis:6379. getaddrinfo failed.
2025-08-05 10:02:04 - app.services.cache_init - ERROR - Failed to initialize cache service: Error 11001 connecting to redis:6379. getaddrinfo failed.
2025-08-05 10:02:04 - app.services.cache_init - ERROR - Cache system initialization failed: Error 11001 connecting to redis:6379. getaddrinfo failed.
2025-08-05 10:07:04 - app.core.cache_warmup - ERROR - 预热关键权限数据失败: (psycopg2.OperationalError) connection to server at "127.0.0.1", port 5432 failed: FATAL:  password authentication failed for user "sys_rev_user"

(Background on this error at: https://sqlalche.me/e/20/e3q8)
2025-08-05 10:07:04 - app.core.cache_warmup - ERROR - 定期缓存刷新失败: (psycopg2.OperationalError) connection to server at "127.0.0.1", port 5432 failed: FATAL:  password authentication failed for user "sys_rev_user"

(Background on this error at: https://sqlalche.me/e/20/e3q8)
2025-08-05 10:12:04 - app.core.cache_warmup - ERROR - 预热关键权限数据失败: (psycopg2.OperationalError) connection to server at "127.0.0.1", port 5432 failed: FATAL:  password authentication failed for user "sys_rev_user"

(Background on this error at: https://sqlalche.me/e/20/e3q8)
2025-08-05 10:12:04 - app.core.cache_warmup - ERROR - 定期缓存刷新失败: (psycopg2.OperationalError) connection to server at "127.0.0.1", port 5432 failed: FATAL:  password authentication failed for user "sys_rev_user"

(Background on this error at: https://sqlalche.me/e/20/e3q8)
2025-08-05 10:17:04 - app.core.cache_warmup - ERROR - 预热关键权限数据失败: (psycopg2.OperationalError) connection to server at "127.0.0.1", port 5432 failed: FATAL:  password authentication failed for user "sys_rev_user"

(Background on this error at: https://sqlalche.me/e/20/e3q8)
2025-08-05 10:17:04 - app.core.cache_warmup - ERROR - 定期缓存刷新失败: (psycopg2.OperationalError) connection to server at "127.0.0.1", port 5432 failed: FATAL:  password authentication failed for user "sys_rev_user"

(Background on this error at: https://sqlalche.me/e/20/e3q8)
2025-08-05 10:22:04 - app.core.cache_warmup - ERROR - 预热关键权限数据失败: (psycopg2.OperationalError) connection to server at "127.0.0.1", port 5432 failed: FATAL:  password authentication failed for user "sys_rev_user"

(Background on this error at: https://sqlalche.me/e/20/e3q8)
2025-08-05 10:22:04 - app.core.cache_warmup - ERROR - 定期缓存刷新失败: (psycopg2.OperationalError) connection to server at "127.0.0.1", port 5432 failed: FATAL:  password authentication failed for user "sys_rev_user"

(Background on this error at: https://sqlalche.me/e/20/e3q8)
2025-08-05 10:27:04 - app.core.cache_warmup - ERROR - 预热关键权限数据失败: (psycopg2.OperationalError) connection to server at "127.0.0.1", port 5432 failed: FATAL:  password authentication failed for user "sys_rev_user"

(Background on this error at: https://sqlalche.me/e/20/e3q8)
2025-08-05 10:27:04 - app.core.cache_warmup - ERROR - 定期缓存刷新失败: (psycopg2.OperationalError) connection to server at "127.0.0.1", port 5432 failed: FATAL:  password authentication failed for user "sys_rev_user"

(Background on this error at: https://sqlalche.me/e/20/e3q8)
2025-08-05 10:32:04 - app.core.cache_warmup - ERROR - 预热关键权限数据失败: (psycopg2.OperationalError) connection to server at "127.0.0.1", port 5432 failed: FATAL:  password authentication failed for user "sys_rev_user"

(Background on this error at: https://sqlalche.me/e/20/e3q8)
2025-08-05 10:32:04 - app.core.cache_warmup - ERROR - 定期缓存刷新失败: (psycopg2.OperationalError) connection to server at "127.0.0.1", port 5432 failed: FATAL:  password authentication failed for user "sys_rev_user"

(Background on this error at: https://sqlalche.me/e/20/e3q8)
2025-08-05 10:34:56 - app.services.cache_init - ERROR - Failed to initialize cache service: Error 11001 connecting to redis:6379. getaddrinfo failed.
2025-08-05 10:34:56 - app.services.cache_init - ERROR - Cache system initialization failed: Error 11001 connecting to redis:6379. getaddrinfo failed.
2025-08-05 10:35:33 - app.core.exceptions - ERROR - Validation Exception: [{'type': 'string_too_short', 'loc': ('body', 'password'), 'msg': 'String should have at least 8 characters', 'input': 'test123', 'ctx': {'min_length': 8}}]
2025-08-05 10:37:10 - app.core.exceptions - ERROR - HTTP Exception: 401 - Could not validate credentials: Not enough segments
2025-08-05 10:37:10 - app.core.exceptions - ERROR - HTTP Exception: 401 - Could not validate credentials: Not enough segments
2025-08-05 10:39:56 - app.core.cache_warmup - ERROR - 预热关键权限数据失败: (psycopg2.OperationalError) connection to server at "127.0.0.1", port 5432 failed: FATAL:  password authentication failed for user "sys_rev_user"

(Background on this error at: https://sqlalche.me/e/20/e3q8)
2025-08-05 10:39:56 - app.core.cache_warmup - ERROR - 定期缓存刷新失败: (psycopg2.OperationalError) connection to server at "127.0.0.1", port 5432 failed: FATAL:  password authentication failed for user "sys_rev_user"

(Background on this error at: https://sqlalche.me/e/20/e3q8)
2025-08-05 10:40:15 - app.services.cache_init - ERROR - Failed to initialize cache service: Error 11001 connecting to redis:6379. getaddrinfo failed.
2025-08-05 10:40:15 - app.services.cache_init - ERROR - Cache system initialization failed: Error 11001 connecting to redis:6379. getaddrinfo failed.
2025-08-05 10:40:22 - app.services.cache_init - ERROR - Failed to initialize cache service: Error 11001 connecting to redis:6379. getaddrinfo failed.
2025-08-05 10:40:22 - app.services.cache_init - ERROR - Cache system initialization failed: Error 11001 connecting to redis:6379. getaddrinfo failed.
2025-08-05 10:40:28 - app.services.cache_init - ERROR - Failed to initialize cache service: Error 11001 connecting to redis:6379. getaddrinfo failed.
2025-08-05 10:40:28 - app.services.cache_init - ERROR - Cache system initialization failed: Error 11001 connecting to redis:6379. getaddrinfo failed.
2025-08-05 10:40:43 - app.services.cache_init - ERROR - Failed to initialize cache service: Error 11001 connecting to redis:6379. getaddrinfo failed.
2025-08-05 10:40:43 - app.services.cache_init - ERROR - Cache system initialization failed: Error 11001 connecting to redis:6379. getaddrinfo failed.
2025-08-05 10:45:43 - app.core.cache_warmup - ERROR - 预热关键权限数据失败: (psycopg2.OperationalError) connection to server at "127.0.0.1", port 5432 failed: FATAL:  password authentication failed for user "sys_rev_user"

(Background on this error at: https://sqlalche.me/e/20/e3q8)
2025-08-05 10:45:43 - app.core.cache_warmup - ERROR - 定期缓存刷新失败: (psycopg2.OperationalError) connection to server at "127.0.0.1", port 5432 failed: FATAL:  password authentication failed for user "sys_rev_user"

(Background on this error at: https://sqlalche.me/e/20/e3q8)
2025-08-05 10:50:43 - app.core.cache_warmup - ERROR - 预热关键权限数据失败: (psycopg2.OperationalError) connection to server at "127.0.0.1", port 5432 failed: FATAL:  password authentication failed for user "sys_rev_user"

(Background on this error at: https://sqlalche.me/e/20/e3q8)
2025-08-05 10:50:43 - app.core.cache_warmup - ERROR - 定期缓存刷新失败: (psycopg2.OperationalError) connection to server at "127.0.0.1", port 5432 failed: FATAL:  password authentication failed for user "sys_rev_user"

(Background on this error at: https://sqlalche.me/e/20/e3q8)
2025-08-05 10:55:43 - app.core.cache_warmup - ERROR - 预热关键权限数据失败: (psycopg2.OperationalError) connection to server at "127.0.0.1", port 5432 failed: FATAL:  password authentication failed for user "sys_rev_user"

(Background on this error at: https://sqlalche.me/e/20/e3q8)
2025-08-05 10:55:43 - app.core.cache_warmup - ERROR - 定期缓存刷新失败: (psycopg2.OperationalError) connection to server at "127.0.0.1", port 5432 failed: FATAL:  password authentication failed for user "sys_rev_user"

(Background on this error at: https://sqlalche.me/e/20/e3q8)
2025-08-05 11:00:04 - app.services.cache_init - ERROR - Failed to initialize cache service: Error 11001 connecting to redis:6379. getaddrinfo failed.
2025-08-05 11:00:04 - app.services.cache_init - ERROR - Cache system initialization failed: Error 11001 connecting to redis:6379. getaddrinfo failed.
2025-08-05 11:00:36 - app.core.cache_warmup - ERROR - 预热用户权限缓存失败: (psycopg2.errors.UndefinedTable) relation "users" does not exist
LINE 2: FROM users 
             ^

[SQL: SELECT users.id AS users_id, users.username AS users_username, users.email AS users_email, users.full_name AS users_full_name, users.hashed_password AS users_hashed_password, users.role AS users_role, users.primary_role_id AS users_primary_role_id, users.employee_id AS users_employee_id, users.department AS users_department, users.position AS users_position, users.phone AS users_phone, users.is_active AS users_is_active, users.is_superuser AS users_is_superuser, users.last_login AS users_last_login, users.login_count AS users_login_count, users.created_at AS users_created_at, users.updated_at AS users_updated_at 
FROM users 
WHERE users.is_active = true 
 LIMIT %(param_1)s]
[parameters: {'param_1': 100}]
(Background on this error at: https://sqlalche.me/e/20/f405)
2025-08-05 11:00:36 - app.core.cache_warmup - ERROR - 缓存预热失败: (psycopg2.errors.UndefinedTable) relation "users" does not exist
LINE 2: FROM users 
             ^

[SQL: SELECT users.id AS users_id, users.username AS users_username, users.email AS users_email, users.full_name AS users_full_name, users.hashed_password AS users_hashed_password, users.role AS users_role, users.primary_role_id AS users_primary_role_id, users.employee_id AS users_employee_id, users.department AS users_department, users.position AS users_position, users.phone AS users_phone, users.is_active AS users_is_active, users.is_superuser AS users_is_superuser, users.last_login AS users_last_login, users.login_count AS users_login_count, users.created_at AS users_created_at, users.updated_at AS users_updated_at 
FROM users 
WHERE users.is_active = true 
 LIMIT %(param_1)s]
[parameters: {'param_1': 100}]
(Background on this error at: https://sqlalche.me/e/20/f405)
2025-08-05 11:00:36 - app.core.cache_warmup - ERROR - 启动缓存预热失败: (psycopg2.errors.UndefinedTable) relation "users" does not exist
LINE 2: FROM users 
             ^

[SQL: SELECT users.id AS users_id, users.username AS users_username, users.email AS users_email, users.full_name AS users_full_name, users.hashed_password AS users_hashed_password, users.role AS users_role, users.primary_role_id AS users_primary_role_id, users.employee_id AS users_employee_id, users.department AS users_department, users.position AS users_position, users.phone AS users_phone, users.is_active AS users_is_active, users.is_superuser AS users_is_superuser, users.last_login AS users_last_login, users.login_count AS users_login_count, users.created_at AS users_created_at, users.updated_at AS users_updated_at 
FROM users 
WHERE users.is_active = true 
 LIMIT %(param_1)s]
[parameters: {'param_1': 100}]
(Background on this error at: https://sqlalche.me/e/20/f405)
2025-08-05 11:00:49 - app.core.cache_warmup - ERROR - 预热用户权限缓存失败: (psycopg2.errors.UndefinedTable) relation "users" does not exist
LINE 2: FROM users 
             ^

[SQL: SELECT users.id AS users_id, users.username AS users_username, users.email AS users_email, users.full_name AS users_full_name, users.hashed_password AS users_hashed_password, users.role AS users_role, users.primary_role_id AS users_primary_role_id, users.employee_id AS users_employee_id, users.department AS users_department, users.position AS users_position, users.phone AS users_phone, users.is_active AS users_is_active, users.is_superuser AS users_is_superuser, users.last_login AS users_last_login, users.login_count AS users_login_count, users.created_at AS users_created_at, users.updated_at AS users_updated_at 
FROM users 
WHERE users.is_active = true 
 LIMIT %(param_1)s]
[parameters: {'param_1': 100}]
(Background on this error at: https://sqlalche.me/e/20/f405)
2025-08-05 11:00:49 - app.core.cache_warmup - ERROR - 缓存预热失败: (psycopg2.errors.UndefinedTable) relation "users" does not exist
LINE 2: FROM users 
             ^

[SQL: SELECT users.id AS users_id, users.username AS users_username, users.email AS users_email, users.full_name AS users_full_name, users.hashed_password AS users_hashed_password, users.role AS users_role, users.primary_role_id AS users_primary_role_id, users.employee_id AS users_employee_id, users.department AS users_department, users.position AS users_position, users.phone AS users_phone, users.is_active AS users_is_active, users.is_superuser AS users_is_superuser, users.last_login AS users_last_login, users.login_count AS users_login_count, users.created_at AS users_created_at, users.updated_at AS users_updated_at 
FROM users 
WHERE users.is_active = true 
 LIMIT %(param_1)s]
[parameters: {'param_1': 100}]
(Background on this error at: https://sqlalche.me/e/20/f405)
2025-08-05 11:00:49 - app.core.cache_warmup - ERROR - 启动缓存预热失败: (psycopg2.errors.UndefinedTable) relation "users" does not exist
LINE 2: FROM users 
             ^

[SQL: SELECT users.id AS users_id, users.username AS users_username, users.email AS users_email, users.full_name AS users_full_name, users.hashed_password AS users_hashed_password, users.role AS users_role, users.primary_role_id AS users_primary_role_id, users.employee_id AS users_employee_id, users.department AS users_department, users.position AS users_position, users.phone AS users_phone, users.is_active AS users_is_active, users.is_superuser AS users_is_superuser, users.last_login AS users_last_login, users.login_count AS users_login_count, users.created_at AS users_created_at, users.updated_at AS users_updated_at 
FROM users 
WHERE users.is_active = true 
 LIMIT %(param_1)s]
[parameters: {'param_1': 100}]
(Background on this error at: https://sqlalche.me/e/20/f405)
2025-08-05 11:05:49 - app.core.cache_warmup - ERROR - 预热关键权限数据失败: (psycopg2.errors.UndefinedTable) relation "users" does not exist
LINE 2: FROM users
             ^

[SQL: SELECT users.id AS users_id, users.username AS users_username, users.email AS users_email, users.full_name AS users_full_name, users.hashed_password AS users_hashed_password, users.role AS users_role, users.primary_role_id AS users_primary_role_id, users.employee_id AS users_employee_id, users.department AS users_department, users.position AS users_position, users.phone AS users_phone, users.is_active AS users_is_active, users.is_superuser AS users_is_superuser, users.last_login AS users_last_login, users.login_count AS users_login_count, users.created_at AS users_created_at, users.updated_at AS users_updated_at 
FROM users]
(Background on this error at: https://sqlalche.me/e/20/f405)
2025-08-05 11:05:49 - app.core.cache_warmup - ERROR - 定期缓存刷新失败: (psycopg2.errors.UndefinedTable) relation "users" does not exist
LINE 2: FROM users
             ^

[SQL: SELECT users.id AS users_id, users.username AS users_username, users.email AS users_email, users.full_name AS users_full_name, users.hashed_password AS users_hashed_password, users.role AS users_role, users.primary_role_id AS users_primary_role_id, users.employee_id AS users_employee_id, users.department AS users_department, users.position AS users_position, users.phone AS users_phone, users.is_active AS users_is_active, users.is_superuser AS users_is_superuser, users.last_login AS users_last_login, users.login_count AS users_login_count, users.created_at AS users_created_at, users.updated_at AS users_updated_at 
FROM users]
(Background on this error at: https://sqlalche.me/e/20/f405)
2025-08-05 11:10:49 - app.core.cache_warmup - ERROR - 预热关键权限数据失败: (psycopg2.errors.UndefinedTable) relation "users" does not exist
LINE 2: FROM users
             ^

[SQL: SELECT users.id AS users_id, users.username AS users_username, users.email AS users_email, users.full_name AS users_full_name, users.hashed_password AS users_hashed_password, users.role AS users_role, users.primary_role_id AS users_primary_role_id, users.employee_id AS users_employee_id, users.department AS users_department, users.position AS users_position, users.phone AS users_phone, users.is_active AS users_is_active, users.is_superuser AS users_is_superuser, users.last_login AS users_last_login, users.login_count AS users_login_count, users.created_at AS users_created_at, users.updated_at AS users_updated_at 
FROM users]
(Background on this error at: https://sqlalche.me/e/20/f405)
2025-08-05 11:10:49 - app.core.cache_warmup - ERROR - 定期缓存刷新失败: (psycopg2.errors.UndefinedTable) relation "users" does not exist
LINE 2: FROM users
             ^

[SQL: SELECT users.id AS users_id, users.username AS users_username, users.email AS users_email, users.full_name AS users_full_name, users.hashed_password AS users_hashed_password, users.role AS users_role, users.primary_role_id AS users_primary_role_id, users.employee_id AS users_employee_id, users.department AS users_department, users.position AS users_position, users.phone AS users_phone, users.is_active AS users_is_active, users.is_superuser AS users_is_superuser, users.last_login AS users_last_login, users.login_count AS users_login_count, users.created_at AS users_created_at, users.updated_at AS users_updated_at 
FROM users]
(Background on this error at: https://sqlalche.me/e/20/f405)
2025-08-05 11:12:31 - app.core.exceptions - ERROR - HTTP Exception: 401 - Could not validate credentials: Not enough segments
2025-08-05 11:12:31 - app.core.exceptions - ERROR - HTTP Exception: 401 - Could not validate credentials: Not enough segments
2025-08-05 11:15:49 - app.core.cache_warmup - ERROR - 预热关键权限数据失败: (psycopg2.errors.UndefinedTable) relation "users" does not exist
LINE 2: FROM users
             ^

[SQL: SELECT users.id AS users_id, users.username AS users_username, users.email AS users_email, users.full_name AS users_full_name, users.hashed_password AS users_hashed_password, users.role AS users_role, users.primary_role_id AS users_primary_role_id, users.employee_id AS users_employee_id, users.department AS users_department, users.position AS users_position, users.phone AS users_phone, users.is_active AS users_is_active, users.is_superuser AS users_is_superuser, users.last_login AS users_last_login, users.login_count AS users_login_count, users.created_at AS users_created_at, users.updated_at AS users_updated_at 
FROM users]
(Background on this error at: https://sqlalche.me/e/20/f405)
2025-08-05 11:15:49 - app.core.cache_warmup - ERROR - 定期缓存刷新失败: (psycopg2.errors.UndefinedTable) relation "users" does not exist
LINE 2: FROM users
             ^

[SQL: SELECT users.id AS users_id, users.username AS users_username, users.email AS users_email, users.full_name AS users_full_name, users.hashed_password AS users_hashed_password, users.role AS users_role, users.primary_role_id AS users_primary_role_id, users.employee_id AS users_employee_id, users.department AS users_department, users.position AS users_position, users.phone AS users_phone, users.is_active AS users_is_active, users.is_superuser AS users_is_superuser, users.last_login AS users_last_login, users.login_count AS users_login_count, users.created_at AS users_created_at, users.updated_at AS users_updated_at 
FROM users]
(Background on this error at: https://sqlalche.me/e/20/f405)
2025-08-05 11:20:49 - app.core.cache_warmup - ERROR - 预热关键权限数据失败: (psycopg2.errors.UndefinedTable) relation "users" does not exist
LINE 2: FROM users
             ^

[SQL: SELECT users.id AS users_id, users.username AS users_username, users.email AS users_email, users.full_name AS users_full_name, users.hashed_password AS users_hashed_password, users.role AS users_role, users.primary_role_id AS users_primary_role_id, users.employee_id AS users_employee_id, users.department AS users_department, users.position AS users_position, users.phone AS users_phone, users.is_active AS users_is_active, users.is_superuser AS users_is_superuser, users.last_login AS users_last_login, users.login_count AS users_login_count, users.created_at AS users_created_at, users.updated_at AS users_updated_at 
FROM users]
(Background on this error at: https://sqlalche.me/e/20/f405)
2025-08-05 11:20:49 - app.core.cache_warmup - ERROR - 定期缓存刷新失败: (psycopg2.errors.UndefinedTable) relation "users" does not exist
LINE 2: FROM users
             ^

[SQL: SELECT users.id AS users_id, users.username AS users_username, users.email AS users_email, users.full_name AS users_full_name, users.hashed_password AS users_hashed_password, users.role AS users_role, users.primary_role_id AS users_primary_role_id, users.employee_id AS users_employee_id, users.department AS users_department, users.position AS users_position, users.phone AS users_phone, users.is_active AS users_is_active, users.is_superuser AS users_is_superuser, users.last_login AS users_last_login, users.login_count AS users_login_count, users.created_at AS users_created_at, users.updated_at AS users_updated_at 
FROM users]
(Background on this error at: https://sqlalche.me/e/20/f405)
2025-08-05 11:25:49 - app.core.cache_warmup - ERROR - 预热关键权限数据失败: (psycopg2.errors.UndefinedTable) relation "users" does not exist
LINE 2: FROM users
             ^

[SQL: SELECT users.id AS users_id, users.username AS users_username, users.email AS users_email, users.full_name AS users_full_name, users.hashed_password AS users_hashed_password, users.role AS users_role, users.primary_role_id AS users_primary_role_id, users.employee_id AS users_employee_id, users.department AS users_department, users.position AS users_position, users.phone AS users_phone, users.is_active AS users_is_active, users.is_superuser AS users_is_superuser, users.last_login AS users_last_login, users.login_count AS users_login_count, users.created_at AS users_created_at, users.updated_at AS users_updated_at 
FROM users]
(Background on this error at: https://sqlalche.me/e/20/f405)
2025-08-05 11:25:49 - app.core.cache_warmup - ERROR - 定期缓存刷新失败: (psycopg2.errors.UndefinedTable) relation "users" does not exist
LINE 2: FROM users
             ^

[SQL: SELECT users.id AS users_id, users.username AS users_username, users.email AS users_email, users.full_name AS users_full_name, users.hashed_password AS users_hashed_password, users.role AS users_role, users.primary_role_id AS users_primary_role_id, users.employee_id AS users_employee_id, users.department AS users_department, users.position AS users_position, users.phone AS users_phone, users.is_active AS users_is_active, users.is_superuser AS users_is_superuser, users.last_login AS users_last_login, users.login_count AS users_login_count, users.created_at AS users_created_at, users.updated_at AS users_updated_at 
FROM users]
(Background on this error at: https://sqlalche.me/e/20/f405)
2025-08-05 11:28:15 - app.core.cache_warmup - ERROR - 预热用户权限缓存失败: (psycopg2.errors.UndefinedTable) relation "users" does not exist
LINE 2: FROM users 
             ^

[SQL: SELECT users.id AS users_id, users.username AS users_username, users.email AS users_email, users.full_name AS users_full_name, users.hashed_password AS users_hashed_password, users.role AS users_role, users.primary_role_id AS users_primary_role_id, users.employee_id AS users_employee_id, users.department AS users_department, users.position AS users_position, users.phone AS users_phone, users.is_active AS users_is_active, users.is_superuser AS users_is_superuser, users.last_login AS users_last_login, users.login_count AS users_login_count, users.created_at AS users_created_at, users.updated_at AS users_updated_at 
FROM users 
WHERE users.is_active = true 
 LIMIT %(param_1)s]
[parameters: {'param_1': 100}]
(Background on this error at: https://sqlalche.me/e/20/f405)
2025-08-05 11:28:15 - app.core.cache_warmup - ERROR - 缓存预热失败: (psycopg2.errors.UndefinedTable) relation "users" does not exist
LINE 2: FROM users 
             ^

[SQL: SELECT users.id AS users_id, users.username AS users_username, users.email AS users_email, users.full_name AS users_full_name, users.hashed_password AS users_hashed_password, users.role AS users_role, users.primary_role_id AS users_primary_role_id, users.employee_id AS users_employee_id, users.department AS users_department, users.position AS users_position, users.phone AS users_phone, users.is_active AS users_is_active, users.is_superuser AS users_is_superuser, users.last_login AS users_last_login, users.login_count AS users_login_count, users.created_at AS users_created_at, users.updated_at AS users_updated_at 
FROM users 
WHERE users.is_active = true 
 LIMIT %(param_1)s]
[parameters: {'param_1': 100}]
(Background on this error at: https://sqlalche.me/e/20/f405)
2025-08-05 11:28:15 - app.core.cache_warmup - ERROR - 启动缓存预热失败: (psycopg2.errors.UndefinedTable) relation "users" does not exist
LINE 2: FROM users 
             ^

[SQL: SELECT users.id AS users_id, users.username AS users_username, users.email AS users_email, users.full_name AS users_full_name, users.hashed_password AS users_hashed_password, users.role AS users_role, users.primary_role_id AS users_primary_role_id, users.employee_id AS users_employee_id, users.department AS users_department, users.position AS users_position, users.phone AS users_phone, users.is_active AS users_is_active, users.is_superuser AS users_is_superuser, users.last_login AS users_last_login, users.login_count AS users_login_count, users.created_at AS users_created_at, users.updated_at AS users_updated_at 
FROM users 
WHERE users.is_active = true 
 LIMIT %(param_1)s]
[parameters: {'param_1': 100}]
(Background on this error at: https://sqlalche.me/e/20/f405)
2025-08-05 11:28:19 - app.core.cache_warmup - ERROR - 预热用户权限缓存失败: (psycopg2.errors.UndefinedTable) relation "users" does not exist
LINE 2: FROM users 
             ^

[SQL: SELECT users.id AS users_id, users.username AS users_username, users.email AS users_email, users.full_name AS users_full_name, users.hashed_password AS users_hashed_password, users.role AS users_role, users.primary_role_id AS users_primary_role_id, users.employee_id AS users_employee_id, users.department AS users_department, users.position AS users_position, users.phone AS users_phone, users.is_active AS users_is_active, users.is_superuser AS users_is_superuser, users.last_login AS users_last_login, users.login_count AS users_login_count, users.created_at AS users_created_at, users.updated_at AS users_updated_at 
FROM users 
WHERE users.is_active = true 
 LIMIT %(param_1)s]
[parameters: {'param_1': 100}]
(Background on this error at: https://sqlalche.me/e/20/f405)
2025-08-05 11:28:19 - app.core.cache_warmup - ERROR - 缓存预热失败: (psycopg2.errors.UndefinedTable) relation "users" does not exist
LINE 2: FROM users 
             ^

[SQL: SELECT users.id AS users_id, users.username AS users_username, users.email AS users_email, users.full_name AS users_full_name, users.hashed_password AS users_hashed_password, users.role AS users_role, users.primary_role_id AS users_primary_role_id, users.employee_id AS users_employee_id, users.department AS users_department, users.position AS users_position, users.phone AS users_phone, users.is_active AS users_is_active, users.is_superuser AS users_is_superuser, users.last_login AS users_last_login, users.login_count AS users_login_count, users.created_at AS users_created_at, users.updated_at AS users_updated_at 
FROM users 
WHERE users.is_active = true 
 LIMIT %(param_1)s]
[parameters: {'param_1': 100}]
(Background on this error at: https://sqlalche.me/e/20/f405)
2025-08-05 11:28:19 - app.core.cache_warmup - ERROR - 启动缓存预热失败: (psycopg2.errors.UndefinedTable) relation "users" does not exist
LINE 2: FROM users 
             ^

[SQL: SELECT users.id AS users_id, users.username AS users_username, users.email AS users_email, users.full_name AS users_full_name, users.hashed_password AS users_hashed_password, users.role AS users_role, users.primary_role_id AS users_primary_role_id, users.employee_id AS users_employee_id, users.department AS users_department, users.position AS users_position, users.phone AS users_phone, users.is_active AS users_is_active, users.is_superuser AS users_is_superuser, users.last_login AS users_last_login, users.login_count AS users_login_count, users.created_at AS users_created_at, users.updated_at AS users_updated_at 
FROM users 
WHERE users.is_active = true 
 LIMIT %(param_1)s]
[parameters: {'param_1': 100}]
(Background on this error at: https://sqlalche.me/e/20/f405)
2025-08-05 11:28:25 - app.core.cache_warmup - ERROR - 预热用户权限缓存失败: (psycopg2.errors.UndefinedTable) relation "users" does not exist
LINE 2: FROM users 
             ^

[SQL: SELECT users.id AS users_id, users.username AS users_username, users.email AS users_email, users.full_name AS users_full_name, users.hashed_password AS users_hashed_password, users.role AS users_role, users.primary_role_id AS users_primary_role_id, users.employee_id AS users_employee_id, users.department AS users_department, users.position AS users_position, users.phone AS users_phone, users.is_active AS users_is_active, users.is_superuser AS users_is_superuser, users.last_login AS users_last_login, users.login_count AS users_login_count, users.created_at AS users_created_at, users.updated_at AS users_updated_at 
FROM users 
WHERE users.is_active = true 
 LIMIT %(param_1)s]
[parameters: {'param_1': 100}]
(Background on this error at: https://sqlalche.me/e/20/f405)
2025-08-05 11:28:25 - app.core.cache_warmup - ERROR - 缓存预热失败: (psycopg2.errors.UndefinedTable) relation "users" does not exist
LINE 2: FROM users 
             ^

[SQL: SELECT users.id AS users_id, users.username AS users_username, users.email AS users_email, users.full_name AS users_full_name, users.hashed_password AS users_hashed_password, users.role AS users_role, users.primary_role_id AS users_primary_role_id, users.employee_id AS users_employee_id, users.department AS users_department, users.position AS users_position, users.phone AS users_phone, users.is_active AS users_is_active, users.is_superuser AS users_is_superuser, users.last_login AS users_last_login, users.login_count AS users_login_count, users.created_at AS users_created_at, users.updated_at AS users_updated_at 
FROM users 
WHERE users.is_active = true 
 LIMIT %(param_1)s]
[parameters: {'param_1': 100}]
(Background on this error at: https://sqlalche.me/e/20/f405)
2025-08-05 11:28:25 - app.core.cache_warmup - ERROR - 启动缓存预热失败: (psycopg2.errors.UndefinedTable) relation "users" does not exist
LINE 2: FROM users 
             ^

[SQL: SELECT users.id AS users_id, users.username AS users_username, users.email AS users_email, users.full_name AS users_full_name, users.hashed_password AS users_hashed_password, users.role AS users_role, users.primary_role_id AS users_primary_role_id, users.employee_id AS users_employee_id, users.department AS users_department, users.position AS users_position, users.phone AS users_phone, users.is_active AS users_is_active, users.is_superuser AS users_is_superuser, users.last_login AS users_last_login, users.login_count AS users_login_count, users.created_at AS users_created_at, users.updated_at AS users_updated_at 
FROM users 
WHERE users.is_active = true 
 LIMIT %(param_1)s]
[parameters: {'param_1': 100}]
(Background on this error at: https://sqlalche.me/e/20/f405)
2025-08-05 12:10:22 - app.core.cache_scheduler - ERROR - Error in cache refresh task: name 'scheduled_cache_refresh' is not defined
2025-08-05 12:15:20 - app.core.exceptions - ERROR - Validation Exception: [{'type': 'missing', 'loc': ('body', 'project_code'), 'msg': 'Field required', 'input': {'name': '浦东支队指挥中心升级改造项目', 'project_type': 'audit', 'priority': 'high', 'deadline': '2025-08-29T16:00:00.000Z'}}]
2025-08-05 12:16:22 - app.core.cache_scheduler - ERROR - Error in cache refresh task: name 'scheduled_cache_refresh' is not defined
2025-08-05 12:22:22 - app.core.cache_scheduler - ERROR - Error in cache refresh task: name 'scheduled_cache_refresh' is not defined
2025-08-05 12:28:22 - app.core.cache_scheduler - ERROR - Error in cache refresh task: name 'scheduled_cache_refresh' is not defined
2025-08-05 12:34:23 - app.core.cache_scheduler - ERROR - Error in cache refresh task: name 'scheduled_cache_refresh' is not defined
